Workbook
Name Slicer_Hovedgruppe: #N/A
Name Slicer_Undergruppe: #N/A

Sheet Workflow
B2: WORKFLOW | Fra situasjonsbilde til realisert effekt
B6: 1. Nåsituasjon | G6: Budsjett, regnskap, avvik, trend og drivere
C9: ↓
B10: 2. EOY-prognose | G10: Transparent rullerende prognose uten nye tiltak
C13: ↓
B14: 3. AI-kandidattiltak | G14: Generer relevante kort- og langsiktige kandidattiltak
C17: ↓
B18: 4. Governance Gate | G18: Kontroller lov, tariff, HMS, tjeneste, personvern og fullmakt
C21: ↓
B22: 5. Optimalisering | G22: Finn forsvarlig kombinasjon som minimerer restavvik og risiko
C25: ↓
B26: 6. Leder godkjenner | G26: Godkjenn, endre eller avvis. Begrunnelse logges
C29: ↓
B30: 7. Ny EOY-prognose | G30: Reberegn scenario med godkjente tiltak
C33: ↓
B34: 8. Effektoppfølging | G34: Mål faktisk realisert økonomisk effekt
C37: ↓
B38: 9. Langsiktig læring | G38: Bruk realisering til neste prognose og økonomiplan

Sheet 1 Nåsituasjon
B2: BO OG MILJØ | budsjettkontroll 2024
B4: Styringsspørsmål: Hvor er avviket, hva driver utviklingen, og er utviklingen midlertidig eller strukturell?
B6: Budsjett YTD | F6: Regnskap YTD | J6: Merforbruk YTD | N6: Avvik %
B7: ='Pivot - måned'!C18 | F7: ='Pivot - måned'!D18 | J7: ='Pivot - måned'!E18 | N7: =IFERROR(-J7/B7,0)
P8: FILTRER VISNINGEN
P10: 01 · MÅNEDSVISNING
P25: Påvirker måneds-KPI og de to øverste diagrammene.
P27: 02 · KONTOPLANDETALJ
B29: LESNING AV AVVIK
B30: Månedsdiagram: negative stolper (mindreforbruk i kroner) er lyserøde, positive stolper (merforbruk i kroner) lysegrønne. Avvik % har motsatt fortegn.
B31: Måneds-KPIene og de to øverste diagrammene leser månedspivoten; hovedgruppe- og undergruppediagrammene har egne pivotkilder.
B32: Måneds-KPI og begge øverste diagrammer følger hovedgruppe-sliceren. Undergruppediagrammet følger sin egen slicer. Gruppediagrammet viser alltid alle.
B33: Ordinære Excel-diagrammer leser pivotresultater via GETPIVOTDATA i skjult Chart Data. Nye kategorier må legges til i diagramkilden.
B34: Oppdater pivottabellene etter endring i tbl_BoMiljo. Slicerutvalgene er uavhengige; sammenlign ikke filtrert måneds-KPI med ufiltrert gruppeavvik.
B35: Merforbruk = regnskap − budsjett. Bokført jan–aug 2024; sep–des er ikke bokført og inngår ikke i diagrammene.
B57: KONTONIVÅ | største drivere bak merforbruket
B58: Topp 10 positive avvik per kontokode, kun Status = Bokført • rangert med største øverst • beløp i kroner

Sheet 2 Prognose EOY
B2: 2 | PROGNOSE END OF YEAR - før nye tiltak
B5: Regnskap YTD | E5: Gjenstående budsjett | H5: Trendjustering | K5: EOY prognose
B6: ='1 Nåsituasjon'!F7 | E6: =SUMIFS(tbl_BoMiljo[Budsjett],tbl_BoMiljo[Status],"Gjenstående budsjett") | H6: =MAX(0,'1 Nåsituasjon'!J7)*$B$20 | K6: =SUM(B6,E6,H6)
B10: Årsbudsjett | E10: EOY avvik | H10: EOY avvik % | K10: Styringssignal
B11: =SUM(tbl_BoMiljo[Budsjett]) | E11: =K6-B11 | H11: =IFERROR(-E11/B11,0) | K11: =IF(H11<=-10%,"RØD",IF(H11<=-5%,"GUL","GRØNN"))
B15: MVP-formel: EOY = Regnskap YTD + gjenstående budsjett + 50 % av positivt YTD-avvik. Formålet er en transparent første prognose som kan sammenlignes med senere modeller.
B19: Trendandel av positivt YTD-avvik (redigerbar forutsetning)
B20: 0.5
B22: PROGNOSE | modell, ikke bokført regnskap
B23: EOY = bokført regnskap + gjenstående budsjett + MAX(0; YTD-merforbruk) × trendandel.
B24: Styringssignal: RØD ved avvik ≤ −10 %, GUL fra −5 % til over −10 %, ellers GRØNN. Negative prosent betyr merforbruk.
B25: Prognosen gjelder dataperioden i Rådata (2024), ikke dagens kalenderår; fornyes når kildedata oppdateres.
B28: MÅNEDLIG UTVIKLING | bokført mot modellert årsslutt
B29: Periode | C29: Budsjett YTD (kr) | D29: Regnskap YTD (kr) | E29: Prognose YTD (kr) | F29: Merforbruk YTD (kr)
B30: 2024-01 | C30: =SUMIFS(tbl_BoMiljo[Budsjett],tbl_BoMiljo[Periode],"<="&B30) | D30: =SUMIFS(tbl_BoMiljo[Regnskap],tbl_BoMiljo[Status],"Bokført",tbl_BoMiljo[Periode],"<="&B30)
B31: 2024-02 | C31: =SUMIFS(tbl_BoMiljo[Budsjett],tbl_BoMiljo[Periode],"<="&B31) | D31: =SUMIFS(tbl_BoMiljo[Regnskap],tbl_BoMiljo[Status],"Bokført",tbl_BoMiljo[Periode],"<="&B31)
B32: 2024-03 | C32: =SUMIFS(tbl_BoMiljo[Budsjett],tbl_BoMiljo[Periode],"<="&B32) | D32: =SUMIFS(tbl_BoMiljo[Regnskap],tbl_BoMiljo[Status],"Bokført",tbl_BoMiljo[Periode],"<="&B32)
B33: 2024-04 | C33: =SUMIFS(tbl_BoMiljo[Budsjett],tbl_BoMiljo[Periode],"<="&B33) | D33: =SUMIFS(tbl_BoMiljo[Regnskap],tbl_BoMiljo[Status],"Bokført",tbl_BoMiljo[Periode],"<="&B33)
B34: 2024-05 | C34: =SUMIFS(tbl_BoMiljo[Budsjett],tbl_BoMiljo[Periode],"<="&B34) | D34: =SUMIFS(tbl_BoMiljo[Regnskap],tbl_BoMiljo[Status],"Bokført",tbl_BoMiljo[Periode],"<="&B34)
B35: 2024-06 | C35: =SUMIFS(tbl_BoMiljo[Budsjett],tbl_BoMiljo[Periode],"<="&B35) | D35: =SUMIFS(tbl_BoMiljo[Regnskap],tbl_BoMiljo[Status],"Bokført",tbl_BoMiljo[Periode],"<="&B35)
B36: 2024-07 | C36: =SUMIFS(tbl_BoMiljo[Budsjett],tbl_BoMiljo[Periode],"<="&B36) | D36: =SUMIFS(tbl_BoMiljo[Regnskap],tbl_BoMiljo[Status],"Bokført",tbl_BoMiljo[Periode],"<="&B36)
B37: 2024-08 | C37: =SUMIFS(tbl_BoMiljo[Budsjett],tbl_BoMiljo[Periode],"<="&B37) | D37: =SUMIFS(tbl_BoMiljo[Regnskap],tbl_BoMiljo[Status],"Bokført",tbl_BoMiljo[Periode],"<="&B37) | E37: =D37 | F37: =IF(ISNUMBER(E37),E37-C37,"")
B38: 2024-09 | C38: =SUMIFS(tbl_BoMiljo[Budsjett],tbl_BoMiljo[Periode],"<="&B38) | E38: =$B$6+SUMIFS(tbl_BoMiljo[Budsjett],tbl_BoMiljo[Status],"Gjenstående budsjett",tbl_BoMiljo[Periode],"<="&B38)+$H$6*(VALUE(RIGHT(B38,2))-8)/4 | F38: =IF(ISNUMBER(E38),E38-C38,"")
B39: 2024-10 | C39: =SUMIFS(tbl_BoMiljo[Budsjett],tbl_BoMiljo[Periode],"<="&B39) | E39: =$B$6+SUMIFS(tbl_BoMiljo[Budsjett],tbl_BoMiljo[Status],"Gjenstående budsjett",tbl_BoMiljo[Periode],"<="&B39)+$H$6*(VALUE(RIGHT(B39,2))-8)/4 | F39: =IF(ISNUMBER(E39),E39-C39,"")
B40: 2024-11 | C40: =SUMIFS(tbl_BoMiljo[Budsjett],tbl_BoMiljo[Periode],"<="&B40) | E40: =$B$6+SUMIFS(tbl_BoMiljo[Budsjett],tbl_BoMiljo[Status],"Gjenstående budsjett",tbl_BoMiljo[Periode],"<="&B40)+$H$6*(VALUE(RIGHT(B40,2))-8)/4 | F40: =IF(ISNUMBER(E40),E40-C40,"")
B41: 2024-12 | C41: =SUMIFS(tbl_BoMiljo[Budsjett],tbl_BoMiljo[Periode],"<="&B41) | E41: =$B$6+SUMIFS(tbl_BoMiljo[Budsjett],tbl_BoMiljo[Status],"Gjenstående budsjett",tbl_BoMiljo[Periode],"<="&B41)+$H$6*(VALUE(RIGHT(B41,2))-8)/4 | F41: =IF(ISNUMBER(E41),E41-C41,"")
B43: Heltrukken regnskapslinje = bokført januar–august. Prognoselinjen starter i august og viser modellert september–desember; ikke bokførte resultater.
B44: Trendjusteringen fordeles jevnt over fire gjenstående måneder for visualisering. Årsslutt i desember avstemmes mot KPI for EOY-prognose.
B45: Etiketter på prognoselinjen = akkumulert merforbruk (prognose minus budsjett), ikke linjens prognosebeløp. August er bokført avvik.

Sheet 3 AI tiltak og effekt
B2: 3 | ACTION TO TAKE • kandidater, kontroll og beslutning
B5: ID | C5: Tiltak | D5: Horisont | E5: Effektbase | F5: Sats | G5: Sannsynlighet | H5: EOY-effekt | I5: Tjenesterisiko | J5: HR/tariff | K5: Governance | L5: Årlig strukturell effekt | M5: Beslutning | N5: Kontroll dokumentert | O5: Godkjent EOY-effekt | P5: Neste steg / handling | Q5: Beslutningssignal
B6: T1 | C6: Oppfølging refusjoner og inntektskrav | D6: Kort | E6: 732705 | F6: 0.08 | G6: 0.85 | H6: 41323.94 | I6: 0.05 | J6: 0.05 | K6: KREVER FAGKONTROLL | L6: 41323.94 | M6: Godkjent | N6: Ja | O6: =IF(AND(M6="Godkjent",N6="Ja"),H6,0) | P6: Avstem refusjonskrav mot grunnlagsbilag; fagkontroll før inndriving. | Notat: Krav avstemt mot NAV refusjonsportal; 41k bekreftet. | Q6: =IF(M6="Avvist","AVVIST",IF(AND(M6="Godkjent",N6="Ja"),"GRØNN",IF(N6="Ja","GUL","RØD")))
B7: T2 | C7: Redusere unødvendig vikarbruk via intern dekning | D7: Kort | E7: 612450.15 | F7: 0.1 | G7: 0.7 | H7: 28871.51 | I7: 0.15 | J7: 0.25 | K7: KREVER HR/TARIFF | L7: 28871.51 | M7: Godkjent | N7: Ja | O7: =IF(AND(M7="Godkjent",N7="Ja"),H7,0) | P7: Analyser turnus og ledig intern kapasitet; HR/tariff og tjenestekvalitet må godkjenne. | Notat: Drøftet med tillitsvalgt iht. HTA § 4; vikarstopp på dagtid. | Q7: =IF(M7="Avvist","AVVIST",IF(AND(M7="Godkjent",N7="Ja"),"GRØNN",IF(N7="Ja","GUL","RØD")))
B8: T3 | C8: Redusere overtid gjennom planlegging | D8: Kort | E8: 1105443.8 | F8: 0.08 | G8: 0.75 | H8: 55076.629 | I8: 0.15 | J8: 0.25 | K8: KREVER HR/TARIFF | L8: 55076.629 | M8: Kandidat | N8: Nei | O8: =IF(AND(M8="Godkjent",N8="Ja"),H8,0) | P8: Gjennomgå overtidsårsaker og arbeidsplan; avklar HR/tariff og HMS. | Notat: Drøftes videre i turnusutvalg. | Q8: =IF(M8="Avvist","AVVIST",IF(AND(M8="Godkjent",N8="Ja"),"GRØNN",IF(N8="Ja","GUL","RØD")))
B9: T4 | C9: Kontroll av ikke-kritiske kjøp | D9: Kort | E9: 155776 | F9: 0.1 | G9: 0.9 | H9: 9519.84 | I9: 0.1 | J9: 0.05 | K9: KREVER FAGKONTROLL | L9: 9519.84 | M9: Kandidat | N9: Nei | O9: =IF(AND(M9="Godkjent",N9="Ja"),H9,0) | P9: Gjennomgå innkjøpslinjer og avtaler; faglig vurdering før endring. | Q9: =IF(M9="Avvist","AVVIST",IF(AND(M9="Godkjent",N9="Ja"),"GRØNN",IF(N9="Ja","GUL","RØD")))
B10: T5 | C10: Turnus- og kapasitetsanalyse | D10: Lang | E10: 4789478.6 | F10: 0.02 | G10: 0.6 | H10: 27473.743 | I10: 0.1 | J10: 0.25 | K10: KREVER HR/TARIFF | L10: 48079.05 | M10: Kandidat | N10: Nei | O10: =IF(AND(M10="Godkjent",N10="Ja"),H10,0) | P10: Utarbeid kapasitets- og turnusanalyse; HR/tariff og tjenesteleder vurderer. | Q10: =IF(M10="Avvist","AVVIST",IF(AND(M10="Godkjent",N10="Ja"),"GRØNN",IF(N10="Ja","GUL","RØD")))
B11: T6 | C11: Digital oppfølging og planprosess | D11: Lang | E11: 17233691 | F11: 0.005 | G11: 0.6 | H11: 30701.073 | I11: 0.05 | J11: 0.05 | K11: KREVER FAGKONTROLL | L11: 42981.502 | M11: Kandidat | N11: Nei | O11: =IF(AND(M11="Godkjent",N11="Ja"),H11,0) | P11: Test digital oppfølgingsprosess i liten skala; fagkontroll og gevinstmåling. | Q11: =IF(M11="Avvist","AVVIST",IF(AND(M11="Godkjent",N11="Ja"),"GRØNN",IF(N11="Ja","GUL","RØD")))
B14: STYRINGSKONTROLL
B15: Tiltak / antall | E15: =COUNTA(B6:B11)
B16: Modellert EOY-effekt | E16: =SUM(H6:H11)
B17: Dokumentert og godkjent effekt | E17: =SUM(O6:O11)
B18: Gjenstår fag-/HR-kontroll | E18: =COUNTIF(N6:N11,"Nei")
B21: BEREGNING OG OPPFØLGING
B22: Effektbase, satser, sannsynlighet, risiko og H/L er eksisterende modellestimater – ikke dokumenterte realiserte besparelser.
B23: H = modellert effekt inneværende år; L = tidligere estimert årlig effekt. Modellen for disse inngangstallene er ikke dokumentert i rådata.
B24: Godkjent effekt i O beregnes først når beslutning = Godkjent OG kontroll dokumentert = Ja. Registrer bare Ja etter fag-/HR-/HMS-/fullmaktskontroll.
B25: Vurder mulig dobbelttelling mellom vikar, overtid, turnus og refusjoner før godkjenning; følg opp faktisk effekt mot regnskap.
B26: Kontrollflagg i K er opprinnelig behovsvurdering, ikke dokumentasjon på gjennomført kontroll.
B27: Beslutningssignal: RØD = kontroll ikke dokumentert; GUL = kontroll dokumentert, ikke godkjent; GRØNN = godkjent og kontroll dokumentert; AVVIST separat.
B30: Viktig: Tiltakene er kandidattiltak og modellestimater. Før et tiltak inngår i anbefalt tiltakspakke må relevant fag-, HR/tariff-, HMS-, fullmakts- og eventuelt juridisk kontroll være gjennomført.

Sheet 4 Ny Prognose EOY
B2: 4 | NY PROGNOSE • scenario og godkjent effekt
B5: EOY avvik før tiltak | E5: Scenario: alle kandidater (ikke godkjent) | H5: Scenario: restavvik etter kandidater | K5: Lukket andel
B6: ='2 Prognose EOY'!E11 | E6: ='3 AI tiltak og effekt'!E16 | H6: =B6-E6 | K6: =IFERROR(E6/B6,0)
B11: Ny prognose er ikke et nytt budsjett. Øvre rad viser et hypotetisk scenario der alle seks kandidater gir anslått effekt. Det godkjente sporet under viser bare effekt fra tiltak som både er godkjent og kontrollert; restavviket må fortsatt følges opp.
B16: GODKJENT SPOR
B17: Årsprognose før tiltak | E17: ='2 Prognose EOY'!K6 | H17: Restavvik / årsbudsjett | K17: =IFERROR(-E20/'2 Prognose EOY'!B11,0)
B18: Godkjent EOY-effekt | E18: ='3 AI tiltak og effekt'!E17
B19: Årsprognose etter godkjente tiltak | E19: =E17-E18
B20: Restavvik mot årsbudsjett | E20: =E19-'2 Prognose EOY'!B11
B21: Godkjente tiltak (antall) | E21: =COUNTIFS('3 AI tiltak og effekt'!M6:M11,"Godkjent",'3 AI tiltak og effekt'!N6:N11,"Ja")
B24: Øverste rad er et hypotetisk fullt kandidat-scenario, ikke en vedtatt gevinst. Godkjent spor nedenfor teller kun dokumenterte godkjenninger.
B25: Inngangsestimatene for tiltak er ikke automatisk oppdatert fra rådata. Revider dem etter hvert regnskapsuttak og kontroller dobbelttelling.
B27: SCENARIOBRO | årsprognose og restavvik i kroner
B29: Utfallsbane | C29: Årsprognose (kr) | D29: Tiltakseffekt (kr) | E29: Restavvik (kr) | G29: Mulig lukket andel · hypotese | J29: Lukket med godkjente tiltak
B30: Før nye tiltak | C30: ='2 Prognose EOY'!K6 | D30: =0 | E30: =C30-'2 Prognose EOY'!B11 | G30: =IFERROR(D31/E30,0) | J30: =IFERROR(D32/E30,0)
B31: Alle kandidater · hypotese | C31: ='2 Prognose EOY'!K6-'3 AI tiltak og effekt'!E16 | D31: ='3 AI tiltak og effekt'!E16 | E31: =C31-'2 Prognose EOY'!B11
B32: Kun dokumentert godkjent | C32: ='4 Ny Prognose EOY'!E19 | D32: ='3 AI tiltak og effekt'!E17 | E32: =C32-'2 Prognose EOY'!B11
G33: Forskjellen er ikke en realisert eller godkjent gevinst.
B34: FAKTISK BESLUTNINGSGRUNNLAG
B35: Kandidatscenario er ikke en vedtatt besparelse. Sammenlign først godkjent spor med årsbudsjettet.
B36: Oppfølging: kontrollér overlapp mellom vikar, overtid og turnus, dokumenter vedtak, og mål faktisk realisert effekt.
B37: Bare tiltak som både har beslutningen «Godkjent» og dokumentert kontroll «Ja», får redusere prognosen.
B56: SLIK LESER DU DIAGRAMMET
B58: Restavvik = årsprognose − årsbudsjett. Positivt beløp betyr merforbruk; diagrammet starter på null for proporsjonal sammenligning.
B60: Før tiltak: bokført regnskap + gjenstående budsjett + trendjustering. Trendandel er redigerbar på prognosearket.
B62: Alle kandidater: seks eksisterende modellanslag trekkes fra prognosen som et hypotetisk fullt utfall, ikke som vedtak.
B64: Godkjent spor: kun effekt fra tiltak med «Godkjent» OG dokumentert kontroll «Ja» trekkes fra prognosen.
B66: Estimert effekt er ikke realisert regnskapseffekt. Forutsetninger, tjenestekvalitet og mulig dobbelttelling må vurderes før iverksetting.
B69: NY ÅRSSLUTTKURVE | godkjent effekt mot kandidatpotensial
B71: Periode | C71: Budsjett YTD | D71: Bokført YTD | E71: Før tiltak | F71: Godkjent prognose | G71: Alle kandidater · hypotese | H71: Godkjent merforbruk YTD (kr)
B72: ='2 Prognose EOY'!B30 | C72: ='2 Prognose EOY'!C30 | D72: ='2 Prognose EOY'!D30
B73: ='2 Prognose EOY'!B31 | C73: ='2 Prognose EOY'!C31 | D73: ='2 Prognose EOY'!D31
B74: ='2 Prognose EOY'!B32 | C74: ='2 Prognose EOY'!C32 | D74: ='2 Prognose EOY'!D32
B75: ='2 Prognose EOY'!B33 | C75: ='2 Prognose EOY'!C33 | D75: ='2 Prognose EOY'!D33
B76: ='2 Prognose EOY'!B34 | C76: ='2 Prognose EOY'!C34 | D76: ='2 Prognose EOY'!D34
B77: ='2 Prognose EOY'!B35 | C77: ='2 Prognose EOY'!C35 | D77: ='2 Prognose EOY'!D35
B78: ='2 Prognose EOY'!B36 | C78: ='2 Prognose EOY'!C36 | D78: ='2 Prognose EOY'!D36
B79: ='2 Prognose EOY'!B37 | C79: ='2 Prognose EOY'!C37 | D79: ='2 Prognose EOY'!D37 | E79: ='2 Prognose EOY'!E37 | F79: =E79 | G79: =E79 | H79: =IF(ISNUMBER(F79),F79-C79,"")
B80: ='2 Prognose EOY'!B38 | C80: ='2 Prognose EOY'!C38 | E80: ='2 Prognose EOY'!E38 | F80: =E80-$E$18*(VALUE(RIGHT(B80,2))-8)/4 | G80: =E80-$E$6*(VALUE(RIGHT(B80,2))-8)/4 | H80: =IF(ISNUMBER(F80),F80-C80,"")
B81: ='2 Prognose EOY'!B39 | C81: ='2 Prognose EOY'!C39 | E81: ='2 Prognose EOY'!E39 | F81: =E81-$E$18*(VALUE(RIGHT(B81,2))-8)/4 | G81: =E81-$E$6*(VALUE(RIGHT(B81,2))-8)/4 | H81: =IF(ISNUMBER(F81),F81-C81,"")
...

Sheet 5 Langsiktig effekt
B2: 5 | LANGSIKTIGE TILTAK - strukturell effekt over tid
B5: Langsiktig EOY-effekt inneværende år | E5: Estimert helårseffekt neste år | H5: Tidshorisont | K5: Formål
B6: =SUMIF('3 AI tiltak og effekt'!D6:D11,"Lang",'3 AI tiltak og effekt'!H6:H11) | E6: =SUMIF('3 AI tiltak og effekt'!D6:D11,"Lang",'3 AI tiltak og effekt'!L6:L11) | H6: 1-4 år | K6: Varig balanse
B9: TO LANGSIKTIGE KANDIDATER | modellanslag, ikke vedtatt effekt
B11: Tiltak | C11: EOY-estimat (kr) | D11: Helårsestimat (kr) | E11: Beslutning | F11: Kontroll | G11: Godkjent helår (kr) | I11: MER ÅRLIG POTENSIAL
B12: T5 · Turnus/kapasitet | C12: ='3 AI tiltak og effekt'!H10 | D12: ='3 AI tiltak og effekt'!L10 | E12: ='3 AI tiltak og effekt'!M10 | F12: ='3 AI tiltak og effekt'!N10 | G12: =IF(AND(E12="Godkjent",F12="Ja"),D12,0) | I12: =D14-C14
B13: T6 · Digital planprosess | C13: ='3 AI tiltak og effekt'!H11 | D13: ='3 AI tiltak og effekt'!L11 | E13: ='3 AI tiltak og effekt'!M11 | F13: ='3 AI tiltak og effekt'!N11 | G13: =IF(AND(E13="Godkjent",F13="Ja"),D13,0) | I13: Mot anslått EOY-effekt
B14: Sum av anslag | C14: =SUM(C12:C13) | D14: =SUM(D12:D13) | G14: =SUM(G12:G13) | I14: =IFERROR(D14/C14,0)
B31: Langsiktige tiltak skal ikke brukes som om årets avvik er løst. De vises separat fordi de primært skal redusere strukturelt kostnadspress og risiko i neste økonomiplanperiode.
B36: SLIK LESES ANALYSEN
B38: 01 · Tid | C38: EOY gjelder 2024-dataperiodens gjenværende måneder. Helår er et modellert årlig nivå ved full effekt, ikke dokumentert resultat for et konkret senere år.
B40: 02 · Forskjell | C40: Økningen mellom EOY- og helårsestimatet er opptrappingspotensial, ikke et tillegg som kan legges til inneværende års prognose.
B42: 03 · Beslutning | C42: Bare tiltak med både «Godkjent» og «Ja» for dokumentert kontroll teller i godkjent helår. Endre beslutning og kontroll på tiltaksarket.
B44: 04 · Tjeneste/HR | C44: T5 krever HR-/tariff- og tjenestekontroll. T6 krever fagkontroll og en liten test med målbar gevinst før utrulling.
B46: 05 · Dobbeltelling | C46: T5 kan overlappe tiltak om vikarbruk og overtid. Dokumenter avgrensning og følg faktisk effekt mot regnskap før beløp tas inn i økonomiplanen.
B48: 06 · Modellgrense | C48: Effektbaser, sannsynligheter og effektestimater er eksisterende kandidatanslag. Underliggende beregning kan ikke etterprøves fra rådata alene.

Sheet Styringsoversikt
B2: BO OG MILJØ | fra status til dokumentert effekt
B3: 2024-data • bokført til og med august • beløp i kroner • positivt avvik = merforbruk
B6: TRINN | C6: NØKKELTALL | D6: BELØP (KR) | E6: BESLUTNING / TOLKNING | F6: KONTROLLMÅL | G6: ANDEL | H6: TRAFIKKLYS (helse)
B7: 01 Status | C7: Bokført YTD-merforbruk | D7: ='1 Nåsituasjon'!J7 | E7: =IF(D7>0,"Merforbruk: identifiser lønns- og månedsdrivere.","Ingen positivt merforbruk i bokført periode.") | F7: YTD-avvik / YTD-budsjett | G7: =IFERROR(-D7/'1 Nåsituasjon'!B7,0) | H7: =1+G7
B8: 02 Prognose | C8: EOY-merforbruk før tiltak | D8: ='2 Prognose EOY'!E11 | E8: =IF(D8>0,"Prognosen er et scenario før nye tiltak; følg opp avvik.","Prognosen ligger innenfor årsbudsjettet.") | F8: EOY-avvik / årsbudsjett | G8: =IFERROR(-D8/D15,0) | H8: =1+G8
B9: 03 Action to Take | C9: Potensial fra seks kandidater | D9: ='3 AI tiltak og effekt'!E16 | E9: =COUNTIFS('3 AI tiltak og effekt'!M6:M11,"Godkjent",'3 AI tiltak og effekt'!N6:N11,"Ja")&" av 6 dokumentert godkjent. Fullfør fag-/HR-kontroll før effekt tas med." | F9: Godkjent / kandidatpotensial | G9: =IFERROR('3 AI tiltak og effekt'!E17/D9,0) | H9: =IF(G9>=1,1,IF(G9>0,0.92,0))
B10: 04 Ny prognose | C10: Restavvik etter godkjente tiltak | D10: ='4 Ny Prognose EOY'!E20 | E10: =IF(D10>0,"Restavvik består og må styres og eskaleres.","Godkjent scenario ligger innenfor årsbudsjettet.") | F10: Restavvik / årsbudsjett | G10: =IFERROR(-D10/D15,0) | H10: =1+G10
F12: Avvik % = (budsjett − regnskap) / budsjett. Merforbruk er negativt: rødt ≤−10 %, gult −10 til −5 %, grønt >−5 %.
B13: SCENARIOBRO | ikke bland kandidater med vedtatte tiltak | F13: Helsescore for trafikklys = 1 + avvik %; kandidatstatus måles separat etter godkjent andel.
B15: Årsbudsjett | D15: ='2 Prognose EOY'!B11
B16: EOY prognose før tiltak | D16: ='2 Prognose EOY'!K6
B17: EOY hvis alle kandidater realiseres | D17: =D16-'3 AI tiltak og effekt'!E16
B18: EOY etter dokumentert godkjente tiltak | D18: ='4 Ny Prognose EOY'!E19
B21: KILDE OG KONTROLL
B22: Status = Bokført: budsjett og regnskap fra tbl_BoMiljo. Gjenstående budsjett tas først med i årsprognosen.
B23: Prognose: bokført regnskap + gjenstående budsjett + 50 % av positivt YTD-merforbruk (justerbar andel i prognosearket).
B24: Tiltakseffektene er eksisterende modellanslag, ikke realiserte resultater; beregningsgrunnlaget bak anslagene er ikke dokumentert i rådata.
B25: Kun tiltak med både «Godkjent» og «Ja» for dokumentert kontroll reduserer godkjent ny prognose. Kontroll mot dobbelttelling kreves.
B26: Det finnes ingen registrerte vedtak eller realiserte effekter ved opprettelse. Bruk tiltaksarkets blå inndatafelt for beslutning og kontroll.

Sheet Pivot - måned
B2: BOKFØRT • månedlig budsjettkontroll
B4: Datakilde: tbl_BoMiljo | Filter: Status = Bokført | Periode: jan–aug 2024
B5: Merforbruk = Regnskap − Budsjett. Positivt tall er ugunstig; negative inntekter er kreditposter.
B7: Status | C7: (Multiple Items)
B9: Periode | C9: Sum Budsjett | D9: Sum Regnskap | E9: Sum Merforbruk
B10: 2024-01 | C10: 1403337 | D10: 1014751.5 | E10: -388585.5
B11: 2024-02 | C11: 1410893 | D11: 2082089.8 | E11: 671196.79
B12: 2024-03 | C12: 1342381 | D12: 1541248.5 | E12: 198867.51
B13: 2024-04 | C13: 2357359 | D13: 2256715.7 | E13: -100643.34
B14: 2024-05 | C14: 1544215 | D14: 1613436.8 | E14: 69221.84
B15: 2024-06 | C15: 241681 | D15: 519336.23 | E15: 277655.23
B16: 2024-07 | C16: 1512209 | D16: 1837523.1 | E16: 325314.07
B17: 2024-08 | C17: 1525162 | D17: 1757749.8 | E17: 232587.82
B18: Grand Total | C18: 11337237 | D18: 12622851 | E18: 1285614.4

Sheet Pivot - kontoplan
B2: AVVIK • kostnadsstruktur og drivere
B4: Begge pivotene bruker hele tbl_BoMiljo; Status er satt til Bokført. Oppdater pivottabellene etter kildeendring.
B5: Beløp i kroner. Inntekter og refusjoner beholder negativt regnskapsfortegn; netto summeres uten fortegnsbytte.
B7: Status | C7: (Multiple Items)
B9: Hovedgruppe | C9: Sum Budsjett | D9: Sum Regnskap | E9: Sum Merforbruk
B10: 1 Lønn | C10: 11025573 | D10: 12175245 | E10: 1149672.3
B11: 2 Utgifter | C11: 311552 | D11: 455666.08 | E11: 144114.08
B12: 3 Inntekter | C12: 112 | D12: -8060 | E12: -8172
B13: Grand Total | C13: 11337237 | D13: 12622851 | E13: 1285614.4
B19: DETALJ • undergruppe
B20: Status | C20: (Multiple Items)
B22: Undergruppe | C22: Sum Budsjett | D22: Sum Regnskap | E22: Sum Merforbruk
B23: 10 Lønn | C23: 11741958 | D23: 12907950 | E23: 1165992.3
B24: 11 Refusjon lønn | C24: -404833 | D24: -277048.19 | E24: 127784.81
B25: 14 Overføringer | C25: 0 | D25: 0 | E25: 0
B26: 15 Finansutgifter | C26: 0 | D26: 9.27 | E26: 9.27
B27: 16 Brukerbetaling | C27: 112 | D27: 0 | E27: -112
B28: 17 Refusjoner | C28: 0 | D28: -8060 | E28: -8060
B29: Grand Total | C29: 11337237 | D29: 12622851 | E29: 1285614.4

Sheet Metode og kontroll
B2: METODE OG KONTROLL
B3: Kilde | C3: Rådata!tbl_BoMiljo (1 056 datarader; 88 kontolinjer × 12 måneder)
B4: Tidsvindu | C4: 2024-01–2024-08 bokført; 2024-09–2024-12 er gjenstående budsjett og ekskludert fra regnskapsdiagrammer.
B5: Populasjon | C5: Status = Bokført (704 rader), med samme filter i alle tre pivottabeller.
B6: Måltall | C6: Sum Budsjett, Sum Regnskap, Sum Merforbruk, gruppert per periode / hovedgruppe / undergruppe.
B7: Fortegn | C7: Merforbruk = Regnskap − Budsjett. Positivt = over budsjett; negativt = under budsjett. Inntekter kan være negative.
B8: Oppdatering | C8: Bruk Excels innebygde Oppdater pivottabell / Oppdater alle når tbl_BoMiljo endres. Diagrammer leser pivotceller.
B9: Begrensning | C9: Diagrammer fra pivotceller er ordinære Excel-diagrammer, ikke native PivotCharts; de følger pivotverdier ved oppdatering, men områdene er låst til dagens antall kategorier.
B10: Kontroll – bokført budsjett | C10: ='Pivot - måned'!C18
B11: Kontroll – bokført regnskap | C11: ='Pivot - måned'!D18
B12: Kontroll – bokført merforbruk | C12: ='Pivot - måned'!E18
B13: Kontroll – kildeberegnet avvik | C13: =SUMIFS(tbl_BoMiljo[Merforbruk],tbl_BoMiljo[Status],"Bokført")
B14: Differanse pivot mot kilde | C14: =C12-C13
B15: Bokførte datarader | C15: =COUNTIF(tbl_BoMiljo[Status],"Bokført")
B16: Gjenstående budsjett-rader | C16: =COUNTIF(tbl_BoMiljo[Status],"Gjenstående budsjett")

Sheet Datamodell
B2: DATAMODELL | Bo og Miljø MVP
B6: Dimensjoner Dim_Dato Dim_Art Dim_Funksjon Dim_Ansvar Dim_Kontoklasse | F6: Fact_Regnskap transaksjon_id KOSTRA keys korrigert_beløp budsjett_beløp | K6: Fact_Prognose EOY avvik modellversjon
E9: → | J9: →
K15: Fact_Alert KPI severity driver confidence
B24: Dim_Tiltak kategori horisont kontrollbehov fullmakt | F24: Fact_Tiltak_Estimat EOY-effekt helårseffekt risiko sannsynlighet | K24: Governance lov/tariff HMS/tjeneste fullmakt status
J27: →
B34: Fact_Scenario EOY før effekt EOY etter | F34: Audit_AI_Actions AI anbefaling human decision begrunnelse | K34: Tiltak_Resultat estimert realisert realiseringsgrad
E37: → | J37: →

Sheet Rådata BoEnhet pr 2tertial
A1: Periode | B1: Måned | C1: Måned_Nr | D1: Tertial | E1: Status | F1: Lokasjon | G1: KOSTRA_Funksjon | H1: Tjenesteområde | I1: Hovedgruppe | J1: Undergruppe | K1: KOSTRA_Art | L1: Kontokode | M1: Kontonavn | N1: Budsjett | O1: Regnskap | P1: Avvik | Q1: Merforbruk
A2: 2024-01 | B2: Januar | C2: 1 | D2: T1 | E2: Bokført | F2: Kommunal Boenhet | G2: 254 | H2: Helse og mestring | I2: 1 Lønn | J2: 10 Lønn | K2: 1010 | L2: 101000 | M2: Fastlønn - ordinære | N2: 821676 | O2: 659882.34 | P2: 161793.66 | Q2: -161793.66
A3: 2024-02 | B3: Februar | C3: 2 | D3: T1 | E3: Bokført | F3: Kommunal Boenhet | G3: 254 | H3: Helse og mestring | I3: 1 Lønn | J3: 10 Lønn | K3: 1010 | L3: 101000 | M3: Fastlønn - ordinære | N3: 821676 | O3: 956490.83 | P3: -134814.83 | Q3: 134814.83
A4: 2024-03 | B4: Mars | C4: 3 | D4: T1 | E4: Bokført | F4: Kommunal Boenhet | G4: 254 | H4: Helse og mestring | I4: 1 Lønn | J4: 10 Lønn | K4: 1010 | L4: 101000 | M4: Fastlønn - ordinære | N4: 821676 | O4: 923021.33 | P4: -101345.33 | Q4: 101345.33
A5: 2024-04 | B5: April | C5: 4 | D5: T1 | E5: Bokført | F5: Kommunal Boenhet | G5: 254 | H5: Helse og mestring | I5: 1 Lønn | J5: 10 Lønn | K5: 1010 | L5: 101000 | M5: Fastlønn - ordinære | N5: 821676 | O5: 804796.85 | P5: 16879.15 | Q5: -16879.15
A6: 2024-05 | B6: Mai | C6: 5 | D6: T2 | E6: Bokført | F6: Kommunal Boenhet | G6: 254 | H6: Helse og mestring | I6: 1 Lønn | J6: 10 Lønn | K6: 1010 | L6: 101000 | M6: Fastlønn - ordinære | N6: 857162 | O6: 920235.95 | P6: -63073.95 | Q6: 63073.95
A7: 2024-06 | B7: Juni | C7: 6 | D7: T2 | E7: Bokført | F7: Kommunal Boenhet | G7: 254 | H7: Helse og mestring | I7: 1 Lønn | J7: 10 Lønn | K7: 1010 | L7: 101000 | M7: Fastlønn - ordinære | N7: -126322 | O7: 111858.5 | P7: -238180.5 | Q7: 238180.5
A8: 2024-07 | B8: Juli | C8: 7 | D8: T2 | E8: Bokført | F8: Kommunal Boenhet | G8: 254 | H8: Helse og mestring | I8: 1 Lønn | J8: 10 Lønn | K8: 1010 | L8: 101000 | M8: Fastlønn - ordinære | N8: 857144 | O8: 953189.12 | P8: -96045.12 | Q8: 96045.12
A9: 2024-08 | B9: August | C9: 8 | D9: T2 | E9: Bokført | F9: Kommunal Boenhet | G9: 254 | H9: Helse og mestring | I9: 1 Lønn | J9: 10 Lønn | K9: 1010 | L9: 101000 | M9: Fastlønn - ordinære | N9: 857162 | O9: 877293.69 | P9: -20131.69 | Q9: 20131.69
A10: 2024-09 | B10: September | C10: 9 | D10: T3 | E10: Gjenstående budsjett | F10: Kommunal Boenhet | G10: 254 | H10: Helse og mestring | I10: 1 Lønn | J10: 10 Lønn | K10: 1010 | L10: 101000 | M10: Fastlønn - ordinære | N10: 857162 | O10: 0 | P10: 0 | Q10: -857162
A11: 2024-10 | B11: Oktober | C11: 10 | D11: T3 | E11: Gjenstående budsjett | F11: Kommunal Boenhet | G11: 254 | H11: Helse og mestring | I11: 1 Lønn | J11: 10 Lønn | K11: 1010 | L11: 101000 | M11: Fastlønn - ordinære | N11: 857162 | O11: 0 | P11: 0 | Q11: -857162
A12: 2024-11 | B12: November | C12: 11 | D12: T3 | E12: Gjenstående budsjett | F12: Kommunal Boenhet | G12: 254 | H12: Helse og mestring | I12: 1 Lønn | J12: 10 Lønn | K12: 1010 | L12: 101000 | M12: Fastlønn - ordinære | N12: 857162 | O12: 0 | P12: 0 | Q12: -857162
A13: 2024-12 | B13: Desember | C13: 12 | D13: T3 | E13: Gjenstående budsjett | F13: Kommunal Boenhet | G13: 254 | H13: Helse og mestring | I13: 1 Lønn | J13: 10 Lønn | K13: 1010 | L13: 101000 | M13: Fastlønn - ordinære | N13: 857364 | O13: 0 | P13: 0 | Q13: -857364
... A1057: 2024-12 | B1057: Desember | C1057: 12 | D1057: T3 | E1057: Gjenstående budsjett | F1057: Kommunal Boenhet | G1057: 254 | H1057: Helse og mestring | I1057: 3 Inntekter | J1057: 17 Refusjoner | K1057: 1770 | L1057: 177000 | M1057: Refusjon fra private | N1057: 0 | O1057: 0 | P1057: 0 | Q1057: 0

Sheet Chart Data
A1: Undergruppe | B1: Merforbruk (kr) | C1: Rang · undergruppe | D1: Periode | E1: Budsjett (kr) | F1: Regnskap (kr) | G1: Merforbruk (kr) | I1: Periode | J1: Merforbruk (kr) | L1: Hovedgruppe | M1: Merforbruk (kr) | N1: Rang · hovedgruppe | O1: Konto · beskrivelse | P1: Merforbruk (kr) | Q1: Rang merforbruk | S1: Topp 10 konto · minste nederst | T1: Merforbruk (kr) | V1: Hovedgruppe · stigende kilde | W1: Merforbruk (kr) | X1: Undergruppe · stigende kilde | Y1: Merforbruk (kr) | AA1: Periode | AB1: Merforbruk > 0 (kr) | AC1: Mindreforbruk < 0 (kr)
A2: 10 Lønn | B2: =IFERROR(GETPIVOTDATA("Sum Merforbruk",'Pivot - kontoplan'!$B$22,"Undergruppe",A2),0) | C2: =COUNTIF($B$2:$B$7,">"&B2)+COUNTIF($B$2:B2,B2) | D2: 2024-01 | E2: =IFERROR(GETPIVOTDATA("Sum Budsjett",'Pivot - måned'!$B$9,"Periode",D2),0) | F2: =IFERROR(GETPIVOTDATA("Sum Regnskap",'Pivot - måned'!$B$9,"Periode",D2),0) | G2: =IFERROR(GETPIVOTDATA("Sum Merforbruk",'Pivot - måned'!$B$9,"Periode",D2),0) | I2: 2024-01 | J2: =G2 | L2: 1 Lønn | M2: =IFERROR(GETPIVOTDATA("Sum Merforbruk",'Pivot - kontoplan'!$B$9,"Hovedgruppe",L2),0) | N2: =COUNTIF($M$2:$M$4,">"&M2)+COUNTIF($M$2:M2,M2) | O2: 101000 · Fastlønn - ordinære | P2: =SUMIFS(tbl_BoMiljo[Merforbruk],tbl_BoMiljo[Status],"Bokført",tbl_BoMiljo[Kontokode],N2) | Q2: =IF(P2>0,COUNTIF($P$2:$P$89,">"&P2)+COUNTIF($P$2:P2,P2),"") | S2: =IFERROR(INDEX($O$2:$O$89,MATCH(11-ROW(A1),$Q$2:$Q$89,0)),"") | T2: =IFERROR(INDEX($P$2:$P$89,MATCH(11-ROW(A1),$Q$2:$Q$89,0)),0) | V2: =INDEX($L$2:$L$4,MATCH(4-ROWS($V$2:V2),$N$2:$N$4,0)) | W2: =INDEX($M$2:$M$4,MATCH(4-ROWS($V$2:V2),$N$2:$N$4,0)) | X2: =INDEX($A$2:$A$7,MATCH(7-ROWS($X$2:X2),$C$2:$C$7,0)) | Y2: =INDEX($B$2:$B$7,MATCH(7-ROWS($X$2:X2),$C$2:$C$7,0)) | AA2: =I2 | AB2: =MAX(J2,0) | AC2: =MIN(J2,0)
A3: 11 Refusjon lønn | B3: =IFERROR(GETPIVOTDATA("Sum Merforbruk",'Pivot - kontoplan'!$B$22,"Undergruppe",A3),0) | C3: =COUNTIF($B$2:$B$7,">"&B3)+COUNTIF($B$2:B3,B3) | D3: 2024-02 | E3: =IFERROR(GETPIVOTDATA("Sum Budsjett",'Pivot - måned'!$B$9,"Periode",D3),0) | F3: =IFERROR(GETPIVOTDATA("Sum Regnskap",'Pivot - måned'!$B$9,"Periode",D3),0) | G3: =IFERROR(GETPIVOTDATA("Sum Merforbruk",'Pivot - måned'!$B$9,"Periode",D3),0) | I3: 2024-02 | J3: =G3 | L3: 2 Utgifter | M3: =IFERROR(GETPIVOTDATA("Sum Merforbruk",'Pivot - kontoplan'!$B$9,"Hovedgruppe",L3),0) | N3: =COUNTIF($M$2:$M$4,">"&M3)+COUNTIF($M$2:M3,M3) | O3: 101030 · Fastlønn - lørdags- og søndagstillegg | P3: =SUMIFS(tbl_BoMiljo[Merforbruk],tbl_BoMiljo[Status],"Bokført",tbl_BoMiljo[Kontokode],N3) | Q3: =IF(P3>0,COUNTIF($P$2:$P$89,">"&P3)+COUNTIF($P$2:P3,P3),"") | S3: =IFERROR(INDEX($O$2:$O$89,MATCH(11-ROW(A2),$Q$2:$Q$89,0)),"") | T3: =IFERROR(INDEX($P$2:$P$89,MATCH(11-ROW(A2),$Q$2:$Q$89,0)),0) | V3: =INDEX($L$2:$L$4,MATCH(4-ROWS($V$2:V3),$N$2:$N$4,0)) | W3: =INDEX($M$2:$M$4,MATCH(4-ROWS($V$2:V3),$N$2:$N$4,0)) | X3: =INDEX($A$2:$A$7,MATCH(7-ROWS($X$2:X3),$C$2:$C$7,0)) | Y3: =INDEX($B$2:$B$7,MATCH(7-ROWS($X$2:X3),$C$2:$C$7,0)) | AA3: =I3 | AB3: =MAX(J3,0) | AC3: =MIN(J3,0)
A4: 14 Overføringer | B4: =IFERROR(GETPIVOTDATA("Sum Merforbruk",'Pivot - kontoplan'!$B$22,"Undergruppe",A4),0) | C4: =COUNTIF($B$2:$B$7,">"&B4)+COUNTIF($B$2:B4,B4) | D4: 2024-03 | E4: =IFERROR(GETPIVOTDATA("Sum Budsjett",'Pivot - måned'!$B$9,"Periode",D4),0) | F4: =IFERROR(GETPIVOTDATA("Sum Regnskap",'Pivot - måned'!$B$9,"Periode",D4),0) | G4: =IFERROR(GETPIVOTDATA("Sum Merforbruk",'Pivot - måned'!$B$9,"Periode",D4),0) | I4: 2024-03 | J4: =G4 | L4: 3 Inntekter | M4: =IFERROR(GETPIVOTDATA("Sum Merforbruk",'Pivot - kontoplan'!$B$9,"Hovedgruppe",L4),0) | N4: =COUNTIF($M$2:$M$4,">"&M4)+COUNTIF($M$2:M4,M4) | O4: 101031 · Fastlønn - kvelds- og nattillegg | P4: =SUMIFS(tbl_BoMiljo[Merforbruk],tbl_BoMiljo[Status],"Bokført",tbl_BoMiljo[Kontokode],N4) | Q4: =IF(P4>0,COUNTIF($P$2:$P$89,">"&P4)+COUNTIF($P$2:P4,P4),"") | S4: =IFERROR(INDEX($O$2:$O$89,MATCH(11-ROW(A3),$Q$2:$Q$89,0)),"") | T4: =IFERROR(INDEX($P$2:$P$89,MATCH(11-ROW(A3),$Q$2:$Q$89,0)),0) | V4: =INDEX($L$2:$L$4,MATCH(4-ROWS($V$2:V4),$N$2:$N$4,0)) | W4: =INDEX($M$2:$M$4,MATCH(4-ROWS($V$2:V4),$N$2:$N$4,0)) | X4: =INDEX($A$2:$A$7,MATCH(7-ROWS($X$2:X4),$C$2:$C$7,0)) | Y4: =INDEX($B$2:$B$7,MATCH(7-ROWS($X$2:X4),$C$2:$C$7,0)) | AA4: =I4 | AB4: =MAX(J4,0) | AC4: =MIN(J4,0)
A5: 15 Finansutgifter | B5: =IFERROR(GETPIVOTDATA("Sum Merforbruk",'Pivot - kontoplan'!$B$22,"Undergruppe",A5),0) | C5: =COUNTIF($B$2:$B$7,">"&B5)+COUNTIF($B$2:B5,B5) | D5: 2024-04 | E5: =IFERROR(GETPIVOTDATA("Sum Budsjett",'Pivot - måned'!$B$9,"Periode",D5),0) | F5: =IFERROR(GETPIVOTDATA("Sum Regnskap",'Pivot - måned'!$B$9,"Periode",D5),0) | G5: =IFERROR(GETPIVOTDATA("Sum Merforbruk",'Pivot - måned'!$B$9,"Periode",D5),0) | I5: 2024-04 | J5: =G5 | N5: 101032 | O5: 101032 · Fastlønn - helligdagstillegg | P5: =SUMIFS(tbl_BoMiljo[Merforbruk],tbl_BoMiljo[Status],"Bokført",tbl_BoMiljo[Kontokode],N5) | Q5: =IF(P5>0,COUNTIF($P$2:$P$89,">"&P5)+COUNTIF($P$2:P5,P5),"") | S5: =IFERROR(INDEX($O$2:$O$89,MATCH(11-ROW(A4),$Q$2:$Q$89,0)),"") | T5: =IFERROR(INDEX($P$2:$P$89,MATCH(11-ROW(A4),$Q$2:$Q$89,0)),0) | X5: =INDEX($A$2:$A$7,MATCH(7-ROWS($X$2:X5),$C$2:$C$7,0)) | Y5: =INDEX($B$2:$B$7,MATCH(7-ROWS($X$2:X5),$C$2:$C$7,0)) | AA5: =I5 | AB5: =MAX(J5,0) | AC5: =MIN(J5,0)
A6: 16 Brukerbetaling | B6: =IFERROR(GETPIVOTDATA("Sum Merforbruk",'Pivot - kontoplan'!$B$22,"Undergruppe",A6),0) | C6: =COUNTIF($B$2:$B$7,">"&B6)+COUNTIF($B$2:B6,B6) | D6: 2024-05 | E6: =IFERROR(GETPIVOTDATA("Sum Budsjett",'Pivot - måned'!$B$9,"Periode",D6),0) | F6: =IFERROR(GETPIVOTDATA("Sum Regnskap",'Pivot - måned'!$B$9,"Periode",D6),0) | G6: =IFERROR(GETPIVOTDATA("Sum Merforbruk",'Pivot - måned'!$B$9,"Periode",D6),0) | I6: 2024-05 | J6: =G6 | N6: 101040 | O6: 101040 · Fastlønn - veiledningstillegg | P6: =SUMIFS(tbl_BoMiljo[Merforbruk],tbl_BoMiljo[Status],"Bokført",tbl_BoMiljo[Kontokode],N6) | Q6: =IF(P6>0,COUNTIF($P$2:$P$89,">"&P6)+COUNTIF($P$2:P6,P6),"") | S6: =IFERROR(INDEX($O$2:$O$89,MATCH(11-ROW(A5),$Q$2:$Q$89,0)),"") | T6: =IFERROR(INDEX($P$2:$P$89,MATCH(11-ROW(A5),$Q$2:$Q$89,0)),0) | X6: =INDEX($A$2:$A$7,MATCH(7-ROWS($X$2:X6),$C$2:$C$7,0)) | Y6: =INDEX($B$2:$B$7,MATCH(7-ROWS($X$2:X6),$C$2:$C$7,0)) | AA6: =I6 | AB6: =MAX(J6,0) | AC6: =MIN(J6,0)
A7: 17 Refusjoner | B7: =IFERROR(GETPIVOTDATA("Sum Merforbruk",'Pivot - kontoplan'!$B$22,"Undergruppe",A7),0) | C7: =COUNTIF($B$2:$B$7,">"&B7)+COUNTIF($B$2:B7,B7) | D7: 2024-06 | E7: =IFERROR(GETPIVOTDATA("Sum Budsjett",'Pivot - måned'!$B$9,"Periode",D7),0) | F7: =IFERROR(GETPIVOTDATA("Sum Regnskap",'Pivot - måned'!$B$9,"Periode",D7),0) | G7: =IFERROR(GETPIVOTDATA("Sum Merforbruk",'Pivot - måned'!$B$9,"Periode",D7),0) | I7: 2024-06 | J7: =G7 | N7: 102000 | O7: 102000 · Vikar - sykefravær - med refusjon | P7: =SUMIFS(tbl_BoMiljo[Merforbruk],tbl_BoMiljo[Status],"Bokført",tbl_BoMiljo[Kontokode],N7) | Q7: =IF(P7>0,COUNTIF($P$2:$P$89,">"&P7)+COUNTIF($P$2:P7,P7),"") | S7: =IFERROR(INDEX($O$2:$O$89,MATCH(11-ROW(A6),$Q$2:$Q$89,0)),"") | T7: =IFERROR(INDEX($P$2:$P$89,MATCH(11-ROW(A6),$Q$2:$Q$89,0)),0) | X7: =INDEX($A$2:$A$7,MATCH(7-ROWS($X$2:X7),$C$2:$C$7,0)) | Y7: =INDEX($B$2:$B$7,MATCH(7-ROWS($X$2:X7),$C$2:$C$7,0)) | AA7: =I7 | AB7: =MAX(J7,0) | AC7: =MIN(J7,0)
D8: 2024-07 | E8: =IFERROR(GETPIVOTDATA("Sum Budsjett",'Pivot - måned'!$B$9,"Periode",D8),0) | F8: =IFERROR(GETPIVOTDATA("Sum Regnskap",'Pivot - måned'!$B$9,"Periode",D8),0) | G8: =IFERROR(GETPIVOTDATA("Sum Merforbruk",'Pivot - måned'!$B$9,"Periode",D8),0) | I8: 2024-07 | J8: =G8 | N8: 102001 | O8: 102001 · Vikar - sykefravær - uten refusjon | P8: =SUMIFS(tbl_BoMiljo[Merforbruk],tbl_BoMiljo[Status],"Bokført",tbl_BoMiljo[Kontokode],N8) | Q8: =IF(P8>0,COUNTIF($P$2:$P$89,">"&P8)+COUNTIF($P$2:P8,P8),"") | S8: =IFERROR(INDEX($O$2:$O$89,MATCH(11-ROW(A7),$Q$2:$Q$89,0)),"") | T8: =IFERROR(INDEX($P$2:$P$89,MATCH(11-ROW(A7),$Q$2:$Q$89,0)),0) | AA8: =I8 | AB8: =MAX(J8,0) | AC8: =MIN(J8,0)
D9: 2024-08 | E9: =IFERROR(GETPIVOTDATA("Sum Budsjett",'Pivot - måned'!$B$9,"Periode",D9),0) | F9: =IFERROR(GETPIVOTDATA("Sum Regnskap",'Pivot - måned'!$B$9,"Periode",D9),0) | G9: =IFERROR(GETPIVOTDATA("Sum Merforbruk",'Pivot - måned'!$B$9,"Periode",D9),0) | I9: 2024-08 | J9: =G9 | N9: 102002 | O9: 102002 · Vikar - foreldrepermisjon | P9: =SUMIFS(tbl_BoMiljo[Merforbruk],tbl_BoMiljo[Status],"Bokført",tbl_BoMiljo[Kontokode],N9) | Q9: =IF(P9>0,COUNTIF($P$2:$P$89,">"&P9)+COUNTIF($P$2:P9,P9),"") | S9: =IFERROR(INDEX($O$2:$O$89,MATCH(11-ROW(A8),$Q$2:$Q$89,0)),"") | T9: =IFERROR(INDEX($P$2:$P$89,MATCH(11-ROW(A8),$Q$2:$Q$89,0)),0) | AA9: =I9 | AB9: =MAX(J9,0) | AC9: =MIN(J9,0)
N10: 102010 | O10: 102010 · Vikar - lønnet perm inkl tillitsverv og velf.perm. | P10: =SUMIFS(tbl_BoMiljo[Merforbruk],tbl_BoMiljo[Status],"Bokført",tbl_BoMiljo[Kontokode],N10) | Q10: =IF(P10>0,COUNTIF($P$2:$P$89,">"&P10)+COUNTIF($P$2:P10,P10),"") | S10: =IFERROR(INDEX($O$2:$O$89,MATCH(11-ROW(A9),$Q$2:$Q$89,0)),"") | T10: =IFERROR(INDEX($P$2:$P$89,MATCH(11-ROW(A9),$Q$2:$Q$89,0)),0)
N11: 102011 | O11: 102011 · Vikar - feriefravær | P11: =SUMIFS(tbl_BoMiljo[Merforbruk],tbl_BoMiljo[Status],"Bokført",tbl_BoMiljo[Kontokode],N11) | Q11: =IF(P11>0,COUNTIF($P$2:$P$89,">"&P11)+COUNTIF($P$2:P11,P11),"") | S11: =IFERROR(INDEX($O$2:$O$89,MATCH(11-ROW(A10),$Q$2:$Q$89,0)),"") | T11: =IFERROR(INDEX($P$2:$P$89,MATCH(11-ROW(A10),$Q$2:$Q$89,0)),0)
N12: 102013 | O12: 102013 · Vikar - korttidsfravær | P12: =SUMIFS(tbl_BoMiljo[Merforbruk],tbl_BoMiljo[Status],"Bokført",tbl_BoMiljo[Kontokode],N12) | Q12: =IF(P12>0,COUNTIF($P$2:$P$89,">"&P12)+COUNTIF($P$2:P12,P12),"")
N13: 102030 | O13: 102030 · Vikar - lørdags- og søndagstillegg | P13: =SUMIFS(tbl_BoMiljo[Merforbruk],tbl_BoMiljo[Status],"Bokført",tbl_BoMiljo[Kontokode],N13) | Q13: =IF(P13>0,COUNTIF($P$2:$P$89,">"&P13)+COUNTIF($P$2:P13,P13),"")
N14: 102031 | O14: 102031 · Vikar - kvelds- og nattillegg | P14: =SUMIFS(tbl_BoMiljo[Merforbruk],tbl_BoMiljo[Status],"Bokført",tbl_BoMiljo[Kontokode],N14) | Q14: =IF(P14>0,COUNTIF($P$2:$P$89,">"&P14)+COUNTIF($P$2:P14,P14),"")
N15: 102032 | O15: 102032 · Vikar - helligdagstillegg | P15: =SUMIFS(tbl_BoMiljo[Merforbruk],tbl_BoMiljo[Status],"Bokført",tbl_BoMiljo[Kontokode],N15) | Q15: =IF(P15>0,COUNTIF($P$2:$P$89,">"&P15)+COUNTIF($P$2:P15,P15),"")
N16: 103000 | O16: 103000 · Ekstrahjelp | P16: =SUMIFS(tbl_BoMiljo[Merforbruk],tbl_BoMiljo[Status],"Bokført",tbl_BoMiljo[Kontokode],N16) | Q16: =IF(P16>0,COUNTIF($P$2:$P$89,">"&P16)+COUNTIF($P$2:P16,P16),"")
N17: 103030 | O17: 103030 · Ekstrahjelp - lørdags- og søndagstillegg | P17: =SUMIFS(tbl_BoMiljo[Merforbruk],tbl_BoMiljo[Status],"Bokført",tbl_BoMiljo[Kontokode],N17) | Q17: =IF(P17>0,COUNTIF($P$2:$P$89,">"&P17)+COUNTIF($P$2:P17,P17),"")
N18: 103031 | O18: 103031 · Ekstrahjelp - kvelds- og nattillegg | P18: =SUMIFS(tbl_BoMiljo[Merforbruk],tbl_BoMiljo[Status],"Bokført",tbl_BoMiljo[Kontokode],N18) | Q18: =IF(P18>0,COUNTIF($P$2:$P$89,">"&P18)+COUNTIF($P$2:P18,P18),"")
N19: 103032 | O19: 103032 · Ekstrahjelp - helligdagstillegg | P19: =SUMIFS(tbl_BoMiljo[Merforbruk],tbl_BoMiljo[Status],"Bokført",tbl_BoMiljo[Kontokode],N19) | Q19: =IF(P19>0,COUNTIF($P$2:$P$89,">"&P19)+COUNTIF($P$2:P19,P19),"")
N20: 103040 | O20: 103040 · Engasjementer / midlertidige stillinger | P20: =SUMIFS(tbl_BoMiljo[Merforbruk],tbl_BoMiljo[Status],"Bokført",tbl_BoMiljo[Kontokode],N20) | Q20: =IF(P20>0,COUNTIF($P$2:$P$89,">"&P20)+COUNTIF($P$2:P20,P20),"")
N21: 103050 | O21: 103050 · Sommer- og sesonghjelp | P21: =SUMIFS(tbl_BoMiljo[Merforbruk],tbl_BoMiljo[Status],"Bokført",tbl_BoMiljo[Kontokode],N21) | Q21: =IF(P21>0,COUNTIF($P$2:$P$89,">"&P21)+COUNTIF($P$2:P21,P21),"")
N22: 104000 | O22: 104000 · Overtidslønn | P22: =SUMIFS(tbl_BoMiljo[Merforbruk],tbl_BoMiljo[Status],"Bokført",tbl_BoMiljo[Kontokode],N22) | Q22: =IF(P22>0,COUNTIF($P$2:$P$89,">"&P22)+COUNTIF($P$2:P22,P22),"")
N23: 105000 | O23: 105000 · Lærlinger | P23: =SUMIFS(tbl_BoMiljo[Merforbruk],tbl_BoMiljo[Status],"Bokført",tbl_BoMiljo[Kontokode],N23) | Q23: =IF(P23>0,COUNTIF($P$2:$P$89,">"&P23)+COUNTIF($P$2:P23,P23),"")
... N89: 177000 | O89: 177000 · Refusjon fra private | P89: =SUMIFS(tbl_BoMiljo[Merforbruk],tbl_BoMiljo[Status],"Bokført",tbl_BoMiljo[Kontokode],N89) | Q89: =IF(P89>0,COUNTIF($P$2:$P$89,">"&P89)+COUNTIF($P$2:P89,P89),"")
